<mujoco model="hinge_chain">
  <compiler eulerseq="zyx" meshdir="parts" texturedir="assets" autolimits="true"/>
  <option>
    <flag filterparent="disable"/>
  </option>
  <default>
    <joint range="-20 20"/>
  </default>
  <asset>
    <texture type="skybox" builtin="gradient" rgb1="0.3 0.5 0.7" rgb2="0 0 0" width="512" height="512"/>
    <texture name="texgeom" type="cube" builtin="flat" mark="cross" width="127" height="1278" rgb1="0.8 0.6 0.4" rgb2="0.8 0.6 0.4" markrgb="1 1 1" random="0.01"/>
    <texture name="texplane" type="2d" builtin="checker" rgb1=".2 .3 .4" rgb2=".1 0.15 0.2" width="512" height="512" mark="cross" markrgb=".8 .8 .8"/>
    <material name="matplane" reflectance="0.3" texture="texplane" texrepeat="1 1" texuniform="true"/>
    <material name="matgeom" texture="texgeom" texuniform="true" rgba="0.8 0.6 .4 1"/>
    <mesh file="hex-q.obj" name="hex" scale="1 1 1"/>
  </asset>
  <worldbody>

  <light cutoff="100" diffuse="1 1 1" dir="-0 0 -1.3" directional="true" exponent="1" pos="0 0 1.3" specular=".8 .8 .8"/>
    <light mode="targetbodycom" target="box0" pos="3 0 4" cutoff="100" diffuse="1 1 1" specular=".8 .8 .8"/>
    <!-- <light mode="targetbodycom" target="box0" pos="3 0 4" cutoff="100" diffuse="1 1 1" specular=".5 .5 .5"/> -->
    <geom name="floor" pos="0 0 0" rgba="0.8 0.9 0.8 1" size="40 40 40" type="plane" material="matplane" conaffinity="1" condim="6" friction="0.8 .0 .0" priority="10"/>
    <body name="box0" pos="0 0 0">
      <joint name="x_slide" type="slide" axis="1 0 0" damping="0.1"/>
      <joint name="y_slide" type="slide" axis="0 1 0" damping="0.1"/>
      <joint name="z_hinge" type="hinge" axis="0 0 1" damping="0.1"/>
      <geom name="box0" type="mesh" mesh="hex" rgba="0.5843137254901961 0.7176470588235294 0.27450980392156865 0.8" mass="1"/>
      <body name="box1" pos="0.16500000000000004 0.09526279441628827 0">
        <joint name="hinge1" type="hinge" axis="0 0 1" pos="-0.08250000000000002 -0.04763139720814413 0"/>
        <geom name="box1" type="mesh" mesh="hex" rgba="0.5843137254901961 0.7176470588235294 0.27450980392156865 0.8" mass="1"/>
        <body name="box2" pos="0.16500000000000004 0.09526279441628827 0">
          <joint name="hinge2" type="hinge" axis="0 0 1" pos="-0.08250000000000002 -0.04763139720814413 0"/>
          <geom name="box2" type="mesh" mesh="hex" rgba="0.5843137254901961 0.7176470588235294 0.27450980392156865 0.8" mass="1"/>
        </body>
      </body>
    </body>
  </worldbody>
</mujoco>